Workbook

Sheet IDF Sint
B2: Desarrollo de IDF Sintética
B4: 1. Parámetros de refencia
C6: Departamento | E6: Norte de Santander
C7: Municipio | E7: Tibú
C8: Región | E8: =LOOKUP(E6,Coeficientes!C3:C35,Coeficientes!B3:B35) -> R1 - Andina
C9: PMx-24H | E9: 108.6
C10: Dias Lluvia | E10: =+VLOOKUP(E7,Filtro!B5:I120,7,FALSE) -> 121.36244
C11: Pto Anual | E11: =+VLOOKUP(E7,Filtro!B5:I120,8,FALSE) -> 3305.3218
C12: Elevación | E12: =+VLOOKUP(E7,Filtro!B5:I120,4,FALSE) -> 40
C13: Ecuación | E13: Ecuación 4
C14: a | E14: =+VLOOKUP(CONCATENATE(E8,"-",E13),Coeficientes!H5:O28,2,FALSE) -> 1.64
C15: b | E15: =+VLOOKUP(CONCATENATE(E8,"-",E13),Coeficientes!H5:O28,3,FALSE) -> 0.19
C16: c | E16: =+VLOOKUP(CONCATENATE(E8,"-",E13),Coeficientes!H5:O28,4,FALSE) -> 0.65
C17: d | E17: =+VLOOKUP(CONCATENATE(E8,"-",E13),Coeficientes!H5:O28,5,FALSE) -> 0.73
C18: e | E18: =+VLOOKUP(CONCATENATE(E8,"-",E13),Coeficientes!H5:O28,6,FALSE) -> -0.13
C19: f | E19: =+VLOOKUP(CONCATENATE(E8,"-",E13),Coeficientes!H5:O28,7,FALSE) -> 0.08
C20: g | E20: =+VLOOKUP(CONCATENATE(E8,"-",E13),Coeficientes!H5:O28,8,FALSE) -> -0.01
B22: 2. Desarrollo de Curvas IDF Sintéticas
C24: =CONCATENATE("Curvas IDF Sintéticas - Municipio de ",E7," Dpto.", E6) -> Curvas IDF Sintéticas - Municipio de Tibú Dpto.Norte de Santander
C26: Duración | E26: 15 | F26: 30 | G26: 45 | H26: 60 | I26: 90 | J26: 120 | K26: 180 | L26: 210 | M26: 240 | N26: 270
C27: Periodo de Retorno, T | D27: 2 | E27: =$E$14*($D27^$E$15)*($E$9^$E$17)*($E$10^$E$18)*IFERROR(($E$11^$E$19),1)*IFERROR(($E$12^$E$20),1)/((E$26/60)^$E$16) -> 139.35413 | F27: =$E$14*($D27^$E$15)*($E$9^$E$17)*($E$10^$E$18)*IFERROR(($E$11^$E$19),1)*IFERROR(($E$12^$E$20),1)/((F$26/60)^$E$16) -> 88.807646 | G27: =$E$14*($D27^$E$15)*($E$9^$E$17)*($E$10^$E$18)*IFERROR(($E$11^$E$19),1)*IFERROR(($E$12^$E$20),1)/((G$26/60)^$E$16) -> 68.232461 | H27: =$E$14*($D27^$E$15)*($E$9^$E$17)*($E$10^$E$18)*IFERROR(($E$11^$E$19),1)*IFERROR(($E$12^$E$20),1)/((H$26/60)^$E$16) -> 56.595364 | I27: =$E$14*($D27^$E$15)*($E$9^$E$17)*($E$10^$E$18)*IFERROR(($E$11^$E$19),1)*IFERROR(($E$12^$E$20),1)/((I$26/60)^$E$16) -> 43.483204 | J27: =$E$14*($D27^$E$15)*($E$9^$E$17)*($E$10^$E$18)*IFERROR(($E$11^$E$19),1)*IFERROR(($E$12^$E$20),1)/((J$26/60)^$E$16) -> 36.067112 | K27: =$E$14*($D27^$E$15)*($E$9^$E$17)*($E$10^$E$18)*IFERROR(($E$11^$E$19),1)*IFERROR(($E$12^$E$20),1)/((K$26/60)^$E$16) -> 27.71099 | L27: =$E$14*($D27^$E$15)*($E$9^$E$17)*($E$10^$E$18)*IFERROR(($E$11^$E$19),1)*IFERROR(($E$12^$E$20),1)/((L$26/60)^$E$16) -> 25.068978 | ... N27: =$E$14*($D27^$E$15)*($E$9^$E$17)*($E$10^$E$18)*IFERROR(($E$11^$E$19),1)*IFERROR(($E$12^$E$20),1)/((N$26/60)^$E$16) -> 21.290837
D28: 3 | E28: =$E$14*($D28^$E$15)*($E$9^$E$17)*($E$10^$E$18)*IFERROR(($E$11^$E$19),1)*IFERROR(($E$12^$E$20),1)/((E$26/60)^$E$16) -> 150.5141 | F28: =$E$14*($D28^$E$15)*($E$9^$E$17)*($E$10^$E$18)*IFERROR(($E$11^$E$19),1)*IFERROR(($E$12^$E$20),1)/((F$26/60)^$E$16) -> 95.919674 | G28: =$E$14*($D28^$E$15)*($E$9^$E$17)*($E$10^$E$18)*IFERROR(($E$11^$E$19),1)*IFERROR(($E$12^$E$20),1)/((G$26/60)^$E$16) -> 73.696757 | H28: =$E$14*($D28^$E$15)*($E$9^$E$17)*($E$10^$E$18)*IFERROR(($E$11^$E$19),1)*IFERROR(($E$12^$E$20),1)/((H$26/60)^$E$16) -> 61.12772 | I28: =$E$14*($D28^$E$15)*($E$9^$E$17)*($E$10^$E$18)*IFERROR(($E$11^$E$19),1)*IFERROR(($E$12^$E$20),1)/((I$26/60)^$E$16) -> 46.965492 | J28: =$E$14*($D28^$E$15)*($E$9^$E$17)*($E$10^$E$18)*IFERROR(($E$11^$E$19),1)*IFERROR(($E$12^$E$20),1)/((J$26/60)^$E$16) -> 38.955493 | K28: =$E$14*($D28^$E$15)*($E$9^$E$17)*($E$10^$E$18)*IFERROR(($E$11^$E$19),1)*IFERROR(($E$12^$E$20),1)/((K$26/60)^$E$16) -> 29.930184 | L28: =$E$14*($D28^$E$15)*($E$9^$E$17)*($E$10^$E$18)*IFERROR(($E$11^$E$19),1)*IFERROR(($E$12^$E$20),1)/((L$26/60)^$E$16) -> 27.07659 | ... N28: =$E$14*($D28^$E$15)*($E$9^$E$17)*($E$10^$E$18)*IFERROR(($E$11^$E$19),1)*IFERROR(($E$12^$E$20),1)/((N$26/60)^$E$16) -> 22.995882
D29: 5 | E29: =$E$14*($D29^$E$15)*($E$9^$E$17)*($E$10^$E$18)*IFERROR(($E$11^$E$19),1)*IFERROR(($E$12^$E$20),1)/((E$26/60)^$E$16) -> 165.85496 | F29: =$E$14*($D29^$E$15)*($E$9^$E$17)*($E$10^$E$18)*IFERROR(($E$11^$E$19),1)*IFERROR(($E$12^$E$20),1)/((F$26/60)^$E$16) -> 105.6961 | G29: =$E$14*($D29^$E$15)*($E$9^$E$17)*($E$10^$E$18)*IFERROR(($E$11^$E$19),1)*IFERROR(($E$12^$E$20),1)/((G$26/60)^$E$16) -> 81.208154 | H29: =$E$14*($D29^$E$15)*($E$9^$E$17)*($E$10^$E$18)*IFERROR(($E$11^$E$19),1)*IFERROR(($E$12^$E$20),1)/((H$26/60)^$E$16) -> 67.358043 | I29: =$E$14*($D29^$E$15)*($E$9^$E$17)*($E$10^$E$18)*IFERROR(($E$11^$E$19),1)*IFERROR(($E$12^$E$20),1)/((I$26/60)^$E$16) -> 51.752358 | J29: =$E$14*($D29^$E$15)*($E$9^$E$17)*($E$10^$E$18)*IFERROR(($E$11^$E$19),1)*IFERROR(($E$12^$E$20),1)/((J$26/60)^$E$16) -> 42.925955 | K29: =$E$14*($D29^$E$15)*($E$9^$E$17)*($E$10^$E$18)*IFERROR(($E$11^$E$19),1)*IFERROR(($E$12^$E$20),1)/((K$26/60)^$E$16) -> 32.980759 | L29: =$E$14*($D29^$E$15)*($E$9^$E$17)*($E$10^$E$18)*IFERROR(($E$11^$E$19),1)*IFERROR(($E$12^$E$20),1)/((L$26/60)^$E$16) -> 29.836318 | ... N29: =$E$14*($D29^$E$15)*($E$9^$E$17)*($E$10^$E$18)*IFERROR(($E$11^$E$19),1)*IFERROR(($E$12^$E$20),1)/((N$26/60)^$E$16) -> 25.339692
D30: 10 | E30: =$E$14*($D30^$E$15)*($E$9^$E$17)*($E$10^$E$18)*IFERROR(($E$11^$E$19),1)*IFERROR(($E$12^$E$20),1)/((E$26/60)^$E$16) -> 189.20132 | F30: =$E$14*($D30^$E$15)*($E$9^$E$17)*($E$10^$E$18)*IFERROR(($E$11^$E$19),1)*IFERROR(($E$12^$E$20),1)/((F$26/60)^$E$16) -> 120.57427 | G30: =$E$14*($D30^$E$15)*($E$9^$E$17)*($E$10^$E$18)*IFERROR(($E$11^$E$19),1)*IFERROR(($E$12^$E$20),1)/((G$26/60)^$E$16) -> 92.639316 | H30: =$E$14*($D30^$E$15)*($E$9^$E$17)*($E$10^$E$18)*IFERROR(($E$11^$E$19),1)*IFERROR(($E$12^$E$20),1)/((H$26/60)^$E$16) -> 76.839612 | I30: =$E$14*($D30^$E$15)*($E$9^$E$17)*($E$10^$E$18)*IFERROR(($E$11^$E$19),1)*IFERROR(($E$12^$E$20),1)/((I$26/60)^$E$16) -> 59.037212 | J30: =$E$14*($D30^$E$15)*($E$9^$E$17)*($E$10^$E$18)*IFERROR(($E$11^$E$19),1)*IFERROR(($E$12^$E$20),1)/((J$26/60)^$E$16) -> 48.968372 | K30: =$E$14*($D30^$E$15)*($E$9^$E$17)*($E$10^$E$18)*IFERROR(($E$11^$E$19),1)*IFERROR(($E$12^$E$20),1)/((K$26/60)^$E$16) -> 37.623253 | L30: =$E$14*($D30^$E$15)*($E$9^$E$17)*($E$10^$E$18)*IFERROR(($E$11^$E$19),1)*IFERROR(($E$12^$E$20),1)/((L$26/60)^$E$16) -> 34.036189 | ... N30: =$E$14*($D30^$E$15)*($E$9^$E$17)*($E$10^$E$18)*IFERROR(($E$11^$E$19),1)*IFERROR(($E$12^$E$20),1)/((N$26/60)^$E$16) -> 28.906601
D31: 15 | E31: =$E$14*($D31^$E$15)*($E$9^$E$17)*($E$10^$E$18)*IFERROR(($E$11^$E$19),1)*IFERROR(($E$12^$E$20),1)/((E$26/60)^$E$16) -> 204.35322 | F31: =$E$14*($D31^$E$15)*($E$9^$E$17)*($E$10^$E$18)*IFERROR(($E$11^$E$19),1)*IFERROR(($E$12^$E$20),1)/((F$26/60)^$E$16) -> 130.23029 | G31: =$E$14*($D31^$E$15)*($E$9^$E$17)*($E$10^$E$18)*IFERROR(($E$11^$E$19),1)*IFERROR(($E$12^$E$20),1)/((G$26/60)^$E$16) -> 100.0582 | H31: =$E$14*($D31^$E$15)*($E$9^$E$17)*($E$10^$E$18)*IFERROR(($E$11^$E$19),1)*IFERROR(($E$12^$E$20),1)/((H$26/60)^$E$16) -> 82.993198 | I31: =$E$14*($D31^$E$15)*($E$9^$E$17)*($E$10^$E$18)*IFERROR(($E$11^$E$19),1)*IFERROR(($E$12^$E$20),1)/((I$26/60)^$E$16) -> 63.76512 | J31: =$E$14*($D31^$E$15)*($E$9^$E$17)*($E$10^$E$18)*IFERROR(($E$11^$E$19),1)*IFERROR(($E$12^$E$20),1)/((J$26/60)^$E$16) -> 52.889931 | K31: =$E$14*($D31^$E$15)*($E$9^$E$17)*($E$10^$E$18)*IFERROR(($E$11^$E$19),1)*IFERROR(($E$12^$E$20),1)/((K$26/60)^$E$16) -> 40.636256 | L31: =$E$14*($D31^$E$15)*($E$9^$E$17)*($E$10^$E$18)*IFERROR(($E$11^$E$19),1)*IFERROR(($E$12^$E$20),1)/((L$26/60)^$E$16) -> 36.761927 | ... N31: =$E$14*($D31^$E$15)*($E$9^$E$17)*($E$10^$E$18)*IFERROR(($E$11^$E$19),1)*IFERROR(($E$12^$E$20),1)/((N$26/60)^$E$16) -> 31.221543
D32: 20 | E32: =$E$14*($D32^$E$15)*($E$9^$E$17)*($E$10^$E$18)*IFERROR(($E$11^$E$19),1)*IFERROR(($E$12^$E$20),1)/((E$26/60)^$E$16) -> 215.834 | F32: =$E$14*($D32^$E$15)*($E$9^$E$17)*($E$10^$E$18)*IFERROR(($E$11^$E$19),1)*IFERROR(($E$12^$E$20),1)/((F$26/60)^$E$16) -> 137.54676 | G32: =$E$14*($D32^$E$15)*($E$9^$E$17)*($E$10^$E$18)*IFERROR(($E$11^$E$19),1)*IFERROR(($E$12^$E$20),1)/((G$26/60)^$E$16) -> 105.67957 | H32: =$E$14*($D32^$E$15)*($E$9^$E$17)*($E$10^$E$18)*IFERROR(($E$11^$E$19),1)*IFERROR(($E$12^$E$20),1)/((H$26/60)^$E$16) -> 87.655841 | I32: =$E$14*($D32^$E$15)*($E$9^$E$17)*($E$10^$E$18)*IFERROR(($E$11^$E$19),1)*IFERROR(($E$12^$E$20),1)/((I$26/60)^$E$16) -> 67.34751 | J32: =$E$14*($D32^$E$15)*($E$9^$E$17)*($E$10^$E$18)*IFERROR(($E$11^$E$19),1)*IFERROR(($E$12^$E$20),1)/((J$26/60)^$E$16) -> 55.861342 | K32: =$E$14*($D32^$E$15)*($E$9^$E$17)*($E$10^$E$18)*IFERROR(($E$11^$E$19),1)*IFERROR(($E$12^$E$20),1)/((K$26/60)^$E$16) -> 42.919242 | L32: =$E$14*($D32^$E$15)*($E$9^$E$17)*($E$10^$E$18)*IFERROR(($E$11^$E$19),1)*IFERROR(($E$12^$E$20),1)/((L$26/60)^$E$16) -> 38.82725 | ... N32: =$E$14*($D32^$E$15)*($E$9^$E$17)*($E$10^$E$18)*IFERROR(($E$11^$E$19),1)*IFERROR(($E$12^$E$20),1)/((N$26/60)^$E$16) -> 32.975601
D33: 50 | E33: =$E$14*($D33^$E$15)*($E$9^$E$17)*($E$10^$E$18)*IFERROR(($E$11^$E$19),1)*IFERROR(($E$12^$E$20),1)/((E$26/60)^$E$16) -> 256.87891 | F33: =$E$14*($D33^$E$15)*($E$9^$E$17)*($E$10^$E$18)*IFERROR(($E$11^$E$19),1)*IFERROR(($E$12^$E$20),1)/((F$26/60)^$E$16) -> 163.70387 | G33: =$E$14*($D33^$E$15)*($E$9^$E$17)*($E$10^$E$18)*IFERROR(($E$11^$E$19),1)*IFERROR(($E$12^$E$20),1)/((G$26/60)^$E$16) -> 125.77654 | H33: =$E$14*($D33^$E$15)*($E$9^$E$17)*($E$10^$E$18)*IFERROR(($E$11^$E$19),1)*IFERROR(($E$12^$E$20),1)/((H$26/60)^$E$16) -> 104.32526 | I33: =$E$14*($D33^$E$15)*($E$9^$E$17)*($E$10^$E$18)*IFERROR(($E$11^$E$19),1)*IFERROR(($E$12^$E$20),1)/((I$26/60)^$E$16) -> 80.154912 | J33: =$E$14*($D33^$E$15)*($E$9^$E$17)*($E$10^$E$18)*IFERROR(($E$11^$E$19),1)*IFERROR(($E$12^$E$20),1)/((J$26/60)^$E$16) -> 66.484432 | K33: =$E$14*($D33^$E$15)*($E$9^$E$17)*($E$10^$E$18)*IFERROR(($E$11^$E$19),1)*IFERROR(($E$12^$E$20),1)/((K$26/60)^$E$16) -> 51.081148 | L33: =$E$14*($D33^$E$15)*($E$9^$E$17)*($E$10^$E$18)*IFERROR(($E$11^$E$19),1)*IFERROR(($E$12^$E$20),1)/((L$26/60)^$E$16) -> 46.210986 | ... N33: =$E$14*($D33^$E$15)*($E$9^$E$17)*($E$10^$E$18)*IFERROR(($E$11^$E$19),1)*IFERROR(($E$12^$E$20),1)/((N$26/60)^$E$16) -> 39.246536

Sheet Normales 1991-2010
A1: Resumen de Normales Climatológicas Estándar 1991 a 2010 - IDEAM
A3: CODIGO | B3: DEPARTAMENTO | C3: MUNICIPIO | D3: CATEGORIA | E3: ESTACIÓN | F3: ALTITUD (m) | G3: LONGITUD | H3: LATITUD | I3: Dias Lluvia | J3: PT Anual
A4: 47067010 | B4: Amazonas | C4: El Encanto | D4: LM | E4: El Encanto | F4: 120 | G4: -73.197139 | H4: -1.7715556 | I4: 191.70113 | J4: 3057.0729
A5: 47060010 | B5: Amazonas | C5: El Encanto | D5: PM | E5: El Encato | F5: 120 | G5: -73.205167 | H5: -1.74851 | I5: 191.11367 | J5: 3021.9891
A6: 44137040 | B6: Amazonas | C6: La Chorrera | D6: LM | E6: Los Monos | F6: 137 | G6: -73.192556 | H6: -0.62833333 | I6: 189.98546 | J6: 3372.3535
A7: 44137030 | B7: Amazonas | C7: La Chorrera | D7: LM | E7: Puerto Belen | F7: 143 | G7: -73.773222 | H7: -0.91511111 | I7: 169.1947
A8: 44187030 | B8: Amazonas | C8: La Pedrera | D8: LM | E8: Bacuri | F8: 101 | G8: -69.47 | H8: -1.23 | I8: 216.04954 | J8: 4170.2491
A9: 44187020 | B9: Amazonas | C9: La Pedrera | D9: PM | E9: La Pedrera | F9: 102 | G9: -69.591583 | H9: -1.3131667 | I9: 161.78216 | J9: 4171.0349
A10: 44157040 | B10: Amazonas | C10: La Pedrera | D10: LM | E10: Manacaro | F10: 109 | G10: -70.18 | H10: -1.53 | I10: 203.97431 | J10: 3706.7623
A11: 44187010 | B11: Amazonas | C11: La Pedrera | D11: LM | E11: Puerto Cordoba | F11: 104 | G11: -69.7255 | H11: -1.2852778 | I11: 180.50339
A12: 48015050 | B12: Amazonas | C12: Leticia | D12: SP | E12: Aeropuerto Vasquez Cobo | F12: 84 | G12: -69.940917 | H12: -4.1938611 | I12: 206.37311 | J12: 3358.8348
A13: 44157020 | B13: Amazonas | C13: Mirití-Paraná (Campoamor) | D13: LM | E13: Las Miranas | F13: 116 | G13: -70.82 | H13: -1.31 | I13: 189.59307 | J13: 3752.4183
A14: 44157030 | B14: Amazonas | C14: Mirití-Paraná (Campoamor) | D14: LM | E14: Maria Manteca | F14: 114 | G14: -70.61 | H14: -1.42 | I14: 207.954 | J14: 3889.6071
A15: 47040020 | B15: Amazonas | C15: Puerto Alegría | D15: PM | E15: El Refugio | F15: 140 | G15: -74.386667 | H15: -0.55916667 | I15: 174.22501 | J15: 3118.5023
A16: 47047020 | B16: Amazonas | C16: Puerto Alegría | D16: LM | E16: Puerto Toloza | F16: 135 | G16: -74.0685 | H16: -1.0495 | I16: 182.15628 | J16: 3549.8876
A17: 47040040 | B17: Amazonas | C17: Puerto Alegría | D17: PM | E17: Remolino | F17: 130 | G17: -73.618944 | H17: -1.2589444 | I17: 197.72625 | J17: 3438.4145
A18: 47087010 | B18: Amazonas | C18: Puerto Arica | D18: PM | E18: Arica - R. Putumayo | F18: 115 | G18: -71.752222 | H18: -2.1468889 | I18: 174.18063 | J18: 3220.4506
A19: 48015040 | B19: Amazonas | C19: Puerto Nariño | D19: CP | E19: Puerto Nariño - AUT | F19: 158 | G19: -70.362639 | H19: -3.7803056 | I19: 156.41491 | J19: 2844.6308
A20: 44150010 | B20: Amazonas | C20: Puerto Santander (Araracuara) | D20: PM | E20: Aguazul | F20: 129 | G20: -72.144944 | H20: -0.55988889 | I20: 242.9 | J20: 3748.8
A21: 44137060 | B21: Amazonas | C21: Puerto Santander (Araracuara) | D21: LM | E21: Angosturas | F21: 134 | G21: -72.720639 | H21: -0.59094444 | I21: 204.26432 | J21: 4669.5456
A22: 44137070 | B22: Amazonas | C22: Puerto Santander (Araracuara) | D22: LM | E22: Monochoa | F22: 133 | G22: -72.549997 | H22: -0.7 | I22: 201 | J22: 3653.5
A23: 44167020 | B23: Amazonas | C23: Puerto Santander (Araracuara) | D23: LM | E23: Santa Isabel | F23: 118 | G23: -71.124056 | H23: -1.0980833 | I23: 194.96964 | J23: 3785.2431
... A58: 12010090 | B58: Antioquia | C58: Carepa | D58: PM | E58: Trigana | F58: 21 | G58: -76.711889 | H58: 7.7476667 | I58: 137.28659 | J58: 3028.9661
A59: 12015060 | B59: Antioquia | C59: Carepa | D59: CO | E59: Tulenapa | F59: 39 | G59: -76.67 | H59: 7.77 | I59: 168.62036
A60: 23080650 | B60: Antioquia | C60: Carmen de Viboral | D60: PM | E60: Campoalegre | F60: 1850 | G60: -75.335611 | H60: 6.0737778 | I60: 198.00665 | J60: 2775.4885
A61: 25020370 | B61: Antioquia | C61: Caucasia | D61: PM | E61: Hacienda La Moneda | F61: 40 | G61: -74.942222 | H61: 8.0366667 | I61: 117.45988 | J61: 3270.3549
A62: 26240160 | B62: Antioquia | C62: Caucasia | D62: PM | E62: La Coquera | F62: 49 | G62: -75.2 | H62: 7.96 | I62: 126.77225 | J62: 2730.6527
A63: 27040030 | B63: Antioquia | C63: Caucasia | D63: PM | E63: La Esmeralda | F63: 100 | G63: -74.853056 | H63: 7.7511111 | I63: 153.29561 | J63: 4331.3399
A64: 25020530 | B64: Antioquia | C64: Caucasia | D64: PM | E64: La Ilusión | F64: 500 | G64: -75.08975 | H64: 8.0255 | I64: 133.32189 | J64: 2644.5552
A65: 26240060 | B65: Antioquia | C65: Caucasia | D65: PM | E65: Manizales | F65: 91 | G65: -74.860353 | H65: 7.75205 | I65: 124.52639 | J65: 2725.7319
A66: 12010030 | B66: Antioquia | C66: Chigorodó | D66: PM | E66: Barranquillita | F66: 18 | G66: -76.7 | H66: 7.57 | I66: 157.45981 | J66: 3649.2094
A67: 11025010 | B67: Antioquia | C67: Ciudad Bolívar | D67: CO | E67: La Mansa | F67: 2018 | G67: -76.084333 | H67: 5.8783056 | I67: 213.72369 | J67: 2463.6822
A68: 23080750 | B68: Antioquia | C68: Cocorná | D68: PM | E68: Cocorna | F68: 1280 | G68: -75.182611 | H68: 6.0533333 | I68: 244.00091 | J68: 4516.8777
A69: 23080740 | B69: Antioquia | C69: Concepción | D69: PM | E69: Concepción | F69: 1280 | G69: -75.259167 | H69: 6.3969444 | I69: 211.01434 | J69: 3049.2094
A70: 26215010 | B70: Antioquia | C70: Concordia | D70: CO | E70: Concordia | F70: 2032 | G70: -75.919528 | H70: 6.0395556 | I70: 179.26743 | J70: 2459.7692
A71: 26210080 | B71: Antioquia | C71: Concordia | D71: PM | E71: La Herradura | F71: 620 | G71: -75.873972 | H71: 6.0992222 | I71: 118.21169 | J71: 2163.0319
A72: 11110030 | B72: Antioquia | C72: Dabeiba | D72: PM | E72: Fuemia | F72: 1046 | G72: -76.252319 | H72: 6.85789 | I72: 122.12437 | J72: 1320.8086
A73: 27015150 | B73: Antioquia | C73: Don Matías | D73: CO | E73: Hacienda El Progreso | F73: 1345 | G73: -75.397167 | H73: 6.4474722 | I73: 181.99942
A74: 27010830 | B74: Antioquia | C74: Entrerrios | D74: PM | E74: San Isidro | F74: 2320 | G74: -75.51575 | H74: 6.5632222 | I74: 192.87154 | J74: 1583.5926
A75: 26200150 | B75: Antioquia | C75: Fredonia | D75: PM | E75: Fredonia | F75: 1650 | G75: -75.685111 | H75: 5.93675 | I75: 198.59327 | J75: 2842.2306
...

Sheet Filtro
B2: Departamento | D2: {='IDF Sint'!E6:E6} -> Norte de Santander
A4: MUNICIPIO | B4: MUNICIPIO | C4: CATEGORIA | D4: ESTACIÓN | E4: ALTITUD (m) | F4: LONGITUD | G4: LATITUD | H4: Dias Lluvia | I4: PT Anual
A5: {=_xlfn._xlws.FILTER('Normales 1991-2010'!B4:J1661,'Normales 1991-2010'!B4:B1661=Filtro!D2,"Revise")} -> Norte de Santander | B5: Ábrego | C5: CP | D5: Abrego Centro Administrativo | E5: 1430 | F5: -73.223056 | G5: 8.0872222 | H5: 111.23539 | I5: 1151.4393
A6: Norte de Santander | B6: Ábrego | C6: PM | D6: Alto El Venado | E6: 1920 | F6: -73.070833 | G6: 8.0888889 | H6: 81.187659 | I6: 1385.1275
A7: Norte de Santander | B7: Ábrego | C7: PM | D7: Bocatoma Rio Frío | E7: 1700 | F7: -73.219278 | G7: 8.0364167 | H7: 102.22785 | I7: 1382.0544
A8: Norte de Santander | B8: Ábrego | C8: PM | D8: El Campanario | E8: 1800 | F8: -73.234444 | G8: 8.0047222 | H8: 116.39578 | I8: 1465.0908
A9: Norte de Santander | B9: Ábrego | C9: PM | D9: El Chorro | E9: 1498 | F9: -73.18375 | G9: 8.0174722 | H9: 93.363167 | I9: 1374.4874
A10: Norte de Santander | B10: Ábrego | C10: CP | D10: La María - AUT | E10: 1800 | F10: -73.211667 | G10: 7.9344444 | H10: 140.20677 | I10: 2001.8849
A11: Norte de Santander | B11: Arboledas | C11: PM | D11: Arboledas | E11: 925 | F11: -72.799722 | G11: 7.6444444 | H11: 106.08423 | I11: 1720.8415
A12: Norte de Santander | B12: Bochalema | C12: PM | D12: La Donjuana 2 | E12: 770 | F12: -72.601389 | G12: 7.6972222 | H12: 80.433217 | I12: 1065.6728
A13: Norte de Santander | B13: Cáchira | C13: CO | D13: Escuela Agrícola Cáchira | E13: 1882 | F13: -73.051667 | G13: 7.7352778 | H13: 121.19839 | I13: 959.01165
A14: Norte de Santander | B14: Cáchira | C14: PM | D14: La Vega | E14: 710 | F14: -73.180556 | G14: 7.6508333 | H14: 120.68427 | I14: 1733.5651
A15: Norte de Santander | B15: Cácota | C15: PM | D15: Cácota | E15: 2645 | F15: -72.643611 | G15: 7.27 | H15: 101.9665 | I15: 666.09048
A16: Norte de Santander | B16: Chinácota | C16: PM | D16: Manzanares | E16: 1350 | F16: -72.590833 | G16: 7.6127778 | H16: 123.92994 | I16: 1426.2818
A17: Norte de Santander | B17: Chitagá | C17: PM | D17: Chitagá | E17: 2410 | F17: -72.664722 | G17: 7.1394444 | H17: 116.26864 | I17: 1013.3763
... A69: Norte de Santander | B69: Villa del Rosario | C69: PM | D69: Villa del Rosario | E69: 522 | F69: -72.477778 | G69: 7.8177778 | H69: 86.696693 | I69: 819.22069

Sheet Coeficientes
B2: REGIÓN | C2: DEPARTAMENTO
B3: R5 - Amazonía | C3: Amazonas | F3: REGIÓN | G3: ECUACIÓN | H3: Concat | I3: COEFICIENTES
B4: R1 - Andina | C4: Antioquia | I4: a | J4: b | K4: c | L4: d | M4: e | N4: f | O4: g
B5: R4 - Orinoquía | C5: Arauca | F5: R0 - Colombia | G5: Ecuación 1 | H5: =CONCATENATE(F5,"-",G5) -> R0 - Colombia-Ecuación 1 | I5: 2.16 | J5: 0.19 | K5: 0.62 | L5: 0.63
B6: R2 - Caribe | C6: Archipiélago de San Andres, Providencia y Santa Catalina | F6: R0 - Colombia | G6: Ecuación 2 | H6: =CONCATENATE(F6,"-",G6) -> R0 - Colombia-Ecuación 2 | I6: 2.83 | J6: 0.19 | K6: 0.62 | L6: 0.62 | M6: -0.04
B7: R2 - Caribe | C7: Atlantico | F7: R0 - Colombia | G7: Ecuación 3 | H7: =CONCATENATE(F7,"-",G7) -> R0 - Colombia-Ecuación 3 | I7: 3.87 | J7: 0.19 | K7: 0.62 | L7: 0.35 | M7: -0.33 | N7: 0.32
B8: R2 - Caribe | C8: Bolívar | F8: R0 - Colombia | G8: Ecuación 4 | H8: =CONCATENATE(F8,"-",G8) -> R0 - Colombia-Ecuación 4 | I8: 3.69 | J8: 0.19 | K8: 0.62 | L8: 0.32 | M8: -0.22 | N8: 0.3 | O8: -0.03
B9: R1 - Andina | C9: Boyacá | F9: R1 - Andina | G9: Ecuación 1 | H9: =CONCATENATE(F9,"-",G9) -> R1 - Andina-Ecuación 1 | I9: 0.94 | J9: 0.18 | K9: 0.66 | L9: 0.83
B10: R1 - Andina | C10: Caldas | F10: R1 - Andina | G10: Ecuación 2 | H10: =CONCATENATE(F10,"-",G10) -> R1 - Andina-Ecuación 2 | I10: 1.22 | J10: 0.19 | K10: 0.66 | L10: 0.83 | M10: -0.05
B11: R5 - Amazonía | C11: Caquetá | F11: R1 - Andina | G11: Ecuación 3 | H11: =CONCATENATE(F11,"-",G11) -> R1 - Andina-Ecuación 3 | I11: 1.61 | J11: 0.19 | K11: 0.65 | L11: 0.75 | M11: -0.15 | N11: 0.08
B12: R4 - Orinoquía | C12: Casanare | F12: R1 - Andina | G12: Ecuación 4 | H12: =CONCATENATE(F12,"-",G12) -> R1 - Andina-Ecuación 4 | I12: 1.64 | J12: 0.19 | K12: 0.65 | L12: 0.73 | M12: -0.13 | N12: 0.08 | O12: -0.01
B13: R3 - Pacífico | C13: Cauca | F13: R2 - Caribe | G13: Ecuación 1 | H13: =CONCATENATE(F13,"-",G13) -> R2 - Caribe-Ecuación 1 | I13: 9.9 | J13: 0.17 | K13: 0.52 | L13: 0.34
B14: R2 - Caribe | C14: Cesar | F14: R2 - Caribe | G14: Ecuación 2 | H14: =CONCATENATE(F14,"-",G14) -> R2 - Caribe-Ecuación 2 | I14: 12.41 | J14: 0.17 | K14: 0.52 | L14: 0.34 | M14: -0.054
B15: R1 - Andina | C15: Cesar Sur | F15: R2 - Caribe | G15: Ecuación 3 | H15: =CONCATENATE(F15,"-",G15) -> R2 - Caribe-Ecuación 3 | I15: 26.69 | J15: 0.17 | K15: 0.52 | L15: 0.35 | M15: 0.167 | N15: -0.259
B16: R3 - Pacífico | C16: Chocó | F16: R2 - Caribe | G16: Ecuación 4 | H16: =CONCATENATE(F16,"-",G16) -> R2 - Caribe-Ecuación 4 | I16: 24.05 | J16: 0.17 | K16: 0.52 | L16: 0.39 | M16: 0.155 | N16: -0.263 | O16: 0
B17: R2 - Caribe | C17: Córdoba | F17: R3 - Pacífico | G17: Ecuación 1 | H17: =CONCATENATE(F17,"-",G17) -> R3 - Pacífico-Ecuación 1 | I17: 8.883 | J17: 0.15 | K17: 0.44 | L17: 0.36
B18: R1 - Andina | C18: Cundinamarca | F18: R3 - Pacífico | G18: Ecuación 2 | H18: =CONCATENATE(F18,"-",G18) -> R3 - Pacífico-Ecuación 2 | I18: 8.694 | J18: 0.15 | K18: 0.44 | L18: 0.94 | M18: -0.52
B19: R4 - Orinoquía | C19: Guainía | F19: R3 - Pacífico | G19: Ecuación 3 | H19: =CONCATENATE(F19,"-",G19) -> R3 - Pacífico-Ecuación 3 | I19: 28.42 | J19: 0.15 | K19: 0.44 | L19: -0.01 | M19: -0.45 | N19: 0.362
B20: R5 - Amazonía | C20: Guaviare | F20: R3 - Pacífico | G20: Ecuación 4 | H20: =CONCATENATE(F20,"-",G20) -> R3 - Pacífico-Ecuación 4 | I20: 5.197 | J20: 0.15 | K20: 0.44 | L20: 0.66 | M20: -0.35 | N20: 0.091 | O20: 0.05
B21: R1 - Andina | C21: Huila | F21: R4 - Orinoquía | G21: Ecuación 1 | H21: =CONCATENATE(F21,"-",G21) -> R4 - Orinoquía-Ecuación 1 | I21: 16.244 | J21: 0.156 | K21: 0.447 | L21: 0.24
B22: R2 - Caribe | C22: La Guajira | F22: R4 - Orinoquía | G22: Ecuación 2 | H22: =CONCATENATE(F22,"-",G22) -> R4 - Orinoquía-Ecuación 2 | I22: 22.769 | J22: 0.156 | K22: 0.447 | L22: 0.319 | M22: -0.136
B23: R2 - Caribe | C23: Magdalena | F23: R4 - Orinoquía | G23: Ecuación 3 | H23: =CONCATENATE(F23,"-",G23) -> R4 - Orinoquía-Ecuación 3 | I23: 22.629 | J23: 0.156 | K23: 0.447 | L23: 0.326 | M23: -0.121 | N23: -0.013
B24: R4 - Orinoquía | C24: Meta | F24: R4 - Orinoquía | G24: Ecuación 4 | H24: =CONCATENATE(F24,"-",G24) -> R4 - Orinoquía-Ecuación 4 | I24: 23.033 | J24: 0.156 | K24: 0.447 | L24: 0.308 | M24: -0.146 | N24: 0.014 | O24: -0.01
B25: R3 - Pacífico | C25: Nariño | F25: R5 - Amazonía | G25: Ecuación 1 | H25: =CONCATENATE(F25,"-",G25) -> R5 - Amazonía-Ecuación 1 | I25: =+I5 -> 2.16 | J25: =+J5 -> 0.19 | K25: =+K5 -> 0.62 | L25: =+L5 -> 0.63
B26: R1 - Andina | C26: Norte de Santander | F26: R5 - Amazonía | G26: Ecuación 2 | H26: =CONCATENATE(F26,"-",G26) -> R5 - Amazonía-Ecuación 2 | I26: =+I6 -> 2.83 | J26: =+J6 -> 0.19 | K26: =+K6 -> 0.62 | L26: =+L6 -> 0.62 | M26: =+M6 -> -0.04
B27: R5 - Amazonía | C27: Putumayo | F27: R5 - Amazonía | G27: Ecuación 3 | H27: =CONCATENATE(F27,"-",G27) -> R5 - Amazonía-Ecuación 3 | I27: =+I7 -> 3.87 | J27: =+J7 -> 0.19 | K27: =+K7 -> 0.62 | L27: =+L7 -> 0.35 | M27: =+M7 -> -0.33 | N27: =+N7 -> 0.32
B28: R1 - Andina | C28: Quindío | F28: R5 - Amazonía | G28: Ecuación 4 | H28: =CONCATENATE(F28,"-",G28) -> R5 - Amazonía-Ecuación 4 | I28: =+I8 -> 3.69 | J28: =+J8 -> 0.19 | K28: =+K8 -> 0.62 | L28: =+L8 -> 0.32 | M28: =+M8 -> -0.22 | N28: =+N8 -> 0.3 | O28: =+O8 -> -0.03
B29: R1 - Andina | C29: RIsaralda | L29: Ref: https://sci.org.co/wp-content/uploads/2018/11/Art4.pdf
B30: R1 - Andina | C30: Santander
B31: R2 - Caribe | C31: Sucre
B32: R1 - Andina | C32: Tolima
B33: R3 - Pacífico | C33: Valle del Cauca
B34: R5 - Amazonía | C34: Vaupes
B35: R4 - Orinoquía | C35: Vichada

Sheet Referencias
B2: Referencias
B4: https://www.ideam.gov.co/sala-de-prensa/informes/Normales%20clim%C3%A1ticas%20est%C3%A1ndar
B6: DESARROLLO DE UNA CALCULADORA DE CURVAS IDF GENERALIZADAS PARA COLOMBIA. Alexander Villamizar (XXIII SEMINARIO NACIONAL DE HIDRÁULICA E HIDROLOGÍA 2018)
B7: https://sci.org.co/wp-content/uploads/2018/11/Art4.pdf
B9: CURVAS SINTETICAS REGIONALIZADAS DE INTENSIDAD-DURACION-FRECUENCIA PARA COLOMBIA. Rodrigo Vargas.
B10: https://1library.co/document/q7o7wjry-vargas-diaz-granados-curvasidf-1998.html

Sheet Metadata
B2: Metadata:
B4: Creado por: Juan David Rodriguez
B5: Correo: ing.juanrodace@gmail.com
B6: Correo: juan.rodrgiueza@escuelaing.edu.co
